Workbook

Sheet Leads
A1: ID | B1: Fecha | C1: Cliente | D1: Telefono | E1: Producto | F1: Valor USD | G1: Estado | H1: Fuente | I1: Prioridad | J1: Notas | K1: Fecha Seguimiento
A2: 1 | B2: 46194 | C2: David Suárez | D2: 0928728463 | E2: Tulipán con Queso | F2: 24 | G2: Nuevo Lead | H2: Google | I2: Alta | J2: Consultó precios | K2: 46199
A3: 2 | B3: 46193 | C3: Carla Reyes | D3: 0941227216 | E3: Helado con Queso | F3: 18 | G3: Propuesta | H3: Referido | I3: Baja | J3: Cotización enviada | K3: 46196
A4: 3 | B4: 46106 | C4: Kevin Rodríguez | D4: 0939587039 | E4: Helado con Queso | F4: 28 | G4: Contactado | H4: WhatsApp | I4: Baja | J4: Se le envió catálogo | K4: 46116
A5: 4 | B5: 46108 | C5: Patricia González | D5: 0930868105 | E5: Waffle | F5: 27 | G5: Contactado | H5: Instagram | I5: Media | J5: Solicitó precios | K5: 46115
A6: 5 | B6: 46185 | C6: Diego Salazar | D6: 0945503389 | E6: Waffle | F6: 26 | G6: Propuesta | H6: Facebook | I6: Baja | J6: Esperando confirmación de pedido | K6: 46192
A7: 6 | B7: 46079 | C7: Tomás Herrera | D7: 0949349722 | E7: Helado con Queso | F7: 24 | G7: Nuevo Lead | H7: Google | I7: Baja | J7: Preguntó por el menú | K7: 46082
A8: 7 | B8: 46107 | C8: Eduardo Paredes | D8: 0940587988 | E8: Helado con Queso | F8: 19 | G8: Contactado | H8: TikTok | I8: Alta | J8: Solicitó precios | K8: 46109
A9: 8 | B9: 46162 | C9: Juan Tomalá | D9: 0959684848 | E9: Waffle | F9: 28 | G9: Propuesta | H9: TikTok | I9: Alta | J9: Esperando confirmación de pedido | K9: 46169
A10: 9 | B10: 46115 | C10: Diego Salazar | D10: 0995225343 | E10: Tulipán con Queso | F10: 21 | G10: Perdido | H10: Instagram | I10: Baja | J10: Precio fuera de presupuesto
A11: 10 | B11: 46138 | C11: Valentina Gómez | D11: 0995899313 | E11: Banana Split | F11: 20 | G11: Contactado | H11: Google | I11: Baja | J11: Solicitó precios | K11: 46144
A12: 11 | B12: 46090 | C12: Iván Cabrera | D12: 0914308421 | E12: Tulipán con Queso | F12: 20 | G12: Interesado | H12: TikTok | I12: Media | J12: Pidió muestra | K12: 46095
A13: 12 | B13: 46081 | C13: Carla Reyes | D13: 0997971488 | E13: Waffle | F13: 30 | G13: Contactado | H13: WhatsApp | I13: Media | J13: Llamada de seguimiento realizada | K13: 46088
A14: 13 | B14: 46164 | C14: Mateo Bravo | D14: 0985345555 | E14: Sundae | F14: 13 | G14: Contactado | H14: Referido | I14: Media | J14: Llamada de seguimiento realizada | K14: 46169
A15: 14 | B15: 46083 | C15: Roberto Castillo | D15: 0939436733 | E15: Helado con Queso | F15: 27 | G15: Propuesta | H15: Instagram | I15: Baja | J15: Esperando confirmación de pedido | K15: 46091
A16: 15 | B16: 46087 | C16: Natalia Cordero | D16: 0931472420 | E16: Waffle | F16: 22 | G16: Nuevo Lead | H16: Google | I16: Media | J16: Consultó precios | K16: 46091
A17: 16 | B17: 46121 | C17: Patricia González | D17: 0984252722 | E17: Sundae | F17: 18 | G17: Propuesta | H17: Facebook | I17: Baja | J17: Cotización enviada | K17: 46131
A18: 17 | B18: 46101 | C18: Joaquín Reyes | D18: 0996028436 | E18: Tulipán con Queso | F18: 24 | G18: Ganado | H18: TikTok | I18: Alta | J18: Pedido entregado
A19: 18 | B19: 46139 | C19: Isabel Navarro | D19: 0933978249 | E19: Sundae | F19: 11 | G19: Contactado | H19: Referido | I19: Alta | J19: Llamada de seguimiento realizada | K19: 46145
A20: 19 | B20: 46133 | C20: Carla Reyes | D20: 0930513739 | E20: Helado Soft | F20: 25 | G20: Perdido | H20: TikTok | I20: Alta | J20: Precio fuera de presupuesto
A21: 20 | B21: 46121 | C21: María López | D21: 0925014631 | E21: Helado con Queso | F21: 23 | G21: Nuevo Lead | H21: TikTok | I21: Media | J21: Primera consulta | K21: 46130
A22: 21 | B22: 46085 | C22: Andrea Torres | D22: 0975228535 | E22: Waffle | F22: 30 | G22: Contactado | H22: Facebook | I22: Baja | J22: Solicitó precios | K22: 46088
A23: 22 | B23: 46137 | C23: Juan Tomalá | D23: 0945575298 | E23: Banana Split | F23: 22 | G23: Perdido | H23: Referido | I23: Baja | J23: Eligió otra opción
A24: 23 | B24: 46101 | C24: Lucía Fonseca | D24: 0951837852 | E24: Banana Split | F24: 17 | G24: Ganado | H24: WhatsApp | I24: Baja | J24: Cliente satisfecho
A25: 24 | B25: 46082 | C25: Luis Vera | D25: 0943273328 | E25: Helado Soft | F25: 24 | G25: Propuesta | H25: Instagram | I25: Alta | J25: Esperando confirmación de pedido | K25: 46091
A26: 25 | B26: 46127 | C26: Camila Vargas | D26: 0939557077 | E26: Waffle | F26: 24 | G26: Ganado | H26: Facebook | I26: Alta | J26: Cliente satisfecho
A27: 26 | B27: 46168 | C27: Gabriela Ortiz | D27: 0954349361 | E27: Tulipán con Queso | F27: 21 | G27: Nuevo Lead | H27: Facebook | I27: Baja | J27: Primera consulta | K27: 46170
A28: 27 | B28: 46135 | C28: Tomás Herrera | D28: 0927758595 | E28: Helado Soft | F28: 19 | G28: Perdido | H28: Google | I28: Baja | J28: Precio fuera de presupuesto
A29: 28 | B29: 46097 | C29: Carla Reyes | D29: 0922660194 | E29: Sundae | F29: 18 | G29: Contactado | H29: Facebook | I29: Baja | J29: Se le envió catálogo | K29: 46105
A30: 29 | B30: 46145 | C30: Eduardo Paredes | D30: 0997705310 | E30: Helado Soft | F30: 23 | G30: Propuesta | H30: Google | I30: Alta | J30: Cotización enviada | K30: 46147
A31: 30 | B31: 46154 | C31: David Suárez | D31: 0935714784 | E31: Sundae | F31: 12 | G31: Perdido | H31: Instagram | I31: Baja | J31: Eligió otra opción
A32: 31 | B32: 46174 | C32: David Suárez | D32: 0920117988 | E32: Banana Split | F32: 18 | G32: Propuesta | H32: WhatsApp | I32: Baja | J32: Cotización enviada | K32: 46183
A33: 32 | B33: 46128 | C33: Andrea Torres | D33: 0941726318 | E33: Waffle | F33: 21 | G33: Perdido | H33: Instagram | I33: Media | J33: Eligió otra opción
A34: 33 | B34: 46087 | C34: Juan Tomalá | D34: 0960864911 | E34: Sundae | F34: 17 | G34: Contactado | H34: Facebook | I34: Media | J34: Se le envió catálogo | K34: 46089
A35: 34 | B35: 46143 | C35: María Zambrano | D35: 0935487660 | E35: Sundae | F35: 19 | G35: Interesado | H35: TikTok | I35: Alta | J35: Interesado en promoción | K35: 46152
A36: 35 | B36: 46128 | C36: Mateo Bravo | D36: 0952091325 | E36: Helado con Queso | F36: 18 | G36: Perdido | H36: Facebook | I36: Alta | J36: Precio fuera de presupuesto
A37: 36 | B37: 46080 | C37: Juan Tomalá | D37: 0917634247 | E37: Sundae | F37: 19 | G37: Ganado | H37: Referido | I37: Alta | J37: Compra realizada
A38: 37 | B38: 46189 | C38: Gabriela Ortiz | D38: 0941568532 | E38: Waffle | F38: 31 | G38: Ganado | H38: WhatsApp | I38: Alta | J38: Cliente satisfecho
A39: 38 | B39: 46121 | C39: Diego Salazar | D39: 0921003626 | E39: Banana Split | F39: 14 | G39: Ganado | H39: WhatsApp | I39: Baja | J39: Cliente satisfecho
A40: 39 | B40: 46157 | C40: Carla Reyes | D40: 0999889098 | E40: Helado con Queso | F40: 22 | G40: Ganado | H40: Google | I40: Media | J40: Compra realizada
...

Sheet Dashboard
A1: Fantasías Heladas CRM | V1: Por Estado | Y1: Por Fuente | AB1: Por Producto | AE1: Por Mes
A2: Resumen de clientes potenciales — valores en USD | V2: Estado | W2: Cantidad | Y2: Fuente | Z2: Cantidad | AB2: Producto | AC2: Cantidad | AE2: Mes | AF2: Cantidad
B3: Total Leads | D3: Valor Pipeline | F3: Ingresos Ganados | H3: Tasa de Conversión | V3: Nuevo Lead | W3: =COUNTIF(Leads!G$2:G$131,V3) | Y3: Facebook | Z3: =COUNTIF(Leads!H$2:H$131,Y3) | AB3: Waffle | AC3: =COUNTIF(Leads!E$2:E$131,AB3) | AE3: 2026-01 | AF3: =SUMPRODUCT((TEXT(Leads!B$2:B$131,"yyyy-mm")=AE3)*1)
B4: =COUNTA(Leads!C2:C131) | D4: =SUMIFS(Leads!F2:F131,Leads!G2:G131,"<>Ganado",Leads!G2:G131,"<>Perdido") | F4: =SUMIFS(Leads!F2:F131,Leads!G2:G131,"Ganado") | H4: =COUNTIF(Leads!G2:G131,"Ganado")/(COUNTIF(Leads!G2:G131,"Ganado")+COUNTIF(Leads!G2:G131,"Perdido")) | V4: Contactado | W4: =COUNTIF(Leads!G$2:G$131,V4) | Y4: Instagram | Z4: =COUNTIF(Leads!H$2:H$131,Y4) | AB4: Banana Split | AC4: =COUNTIF(Leads!E$2:E$131,AB4) | AE4: 2026-02 | AF4: =SUMPRODUCT((TEXT(Leads!B$2:B$131,"yyyy-mm")=AE4)*1)
V5: Interesado | W5: =COUNTIF(Leads!G$2:G$131,V5) | Y5: TikTok | Z5: =COUNTIF(Leads!H$2:H$131,Y5) | AB5: Helado Soft | AC5: =COUNTIF(Leads!E$2:E$131,AB5) | AE5: 2026-03 | AF5: =SUMPRODUCT((TEXT(Leads!B$2:B$131,"yyyy-mm")=AE5)*1)
V6: Propuesta | W6: =COUNTIF(Leads!G$2:G$131,V6) | Y6: WhatsApp | Z6: =COUNTIF(Leads!H$2:H$131,Y6) | AB6: Sundae | AC6: =COUNTIF(Leads!E$2:E$131,AB6) | AE6: 2026-04 | AF6: =SUMPRODUCT((TEXT(Leads!B$2:B$131,"yyyy-mm")=AE6)*1)
V7: Ganado | W7: =COUNTIF(Leads!G$2:G$131,V7) | Y7: Referido | Z7: =COUNTIF(Leads!H$2:H$131,Y7) | AB7: Helado con Queso | AC7: =COUNTIF(Leads!E$2:E$131,AB7) | AE7: 2026-05 | AF7: =SUMPRODUCT((TEXT(Leads!B$2:B$131,"yyyy-mm")=AE7)*1)
V8: Perdido | W8: =COUNTIF(Leads!G$2:G$131,V8) | Y8: Google | Z8: =COUNTIF(Leads!H$2:H$131,Y8) | AB8: Tulipán con Queso | AC8: =COUNTIF(Leads!E$2:E$131,AB8) | AE8: 2026-06 | AF8: =SUMPRODUCT((TEXT(Leads!B$2:B$131,"yyyy-mm")=AE8)*1)
